Traceback (most recent call last):
  File "/home/yuda/code/climatematch/course-content/venv/lib/python3.8/site-packages/nbclient/client.py", line 730, in _async_poll_for_reply
    msg = await ensure_async(self.kc.shell_channel.get_msg(timeout=new_timeout))
  File "/home/yuda/code/climatematch/course-content/venv/lib/python3.8/site-packages/nbclient/util.py", line 96, in ensure_async
    result = await obj
  File "/home/yuda/code/climatematch/course-content/venv/lib/python3.8/site-packages/jupyter_client/channels.py", line 230, in get_msg
    raise Empty
_queue.Empty

During handling of the above exception, another exception occurred:

Traceback (most recent call last):
  File "/home/yuda/code/climatematch/course-content/venv/lib/python3.8/site-packages/jupyter_cache/executors/utils.py", line 51, in single_nb_execution
    executenb(
  File "/home/yuda/code/climatematch/course-content/venv/lib/python3.8/site-packages/nbclient/client.py", line 1204, in execute
    return NotebookClient(nb=nb, resources=resources, km=km, **kwargs).execute()
  File "/home/yuda/code/climatematch/course-content/venv/lib/python3.8/site-packages/nbclient/util.py", line 84, in wrapped
    return just_run(coro(*args, **kwargs))
  File "/home/yuda/code/climatematch/course-content/venv/lib/python3.8/site-packages/nbclient/util.py", line 62, in just_run
    return loop.run_until_complete(coro)
  File "/usr/lib/python3.8/asyncio/base_events.py", line 616, in run_until_complete
    return future.result()
  File "/home/yuda/code/climatematch/course-content/venv/lib/python3.8/site-packages/nbclient/client.py", line 663, in async_execute
    await self.async_execute_cell(
  File "/home/yuda/code/climatematch/course-content/venv/lib/python3.8/site-packages/nbclient/client.py", line 949, in async_execute_cell
    exec_reply = await self.task_poll_for_reply
  File "/home/yuda/code/climatematch/course-content/venv/lib/python3.8/site-packages/nbclient/client.py", line 754, in _async_poll_for_reply
    await self._async_handle_timeout(timeout, cell)
  File "/home/yuda/code/climatematch/course-content/venv/lib/python3.8/site-packages/nbclient/client.py", line 801, in _async_handle_timeout
    raise CellTimeoutError.error_from_timeout_and_cell(
nbclient.exceptions.CellTimeoutError: A cell timed out while it was being executed, after 60 seconds.
The message was: Cell execution timed out.
Here is a preview of the cell contents:
-------------------
# gpp data is acquired from this work: https://essd.copernicus.org/articles/14/1063/2022/
url_GPP='https://researchdata.tuwien.ac.at/records/1k7aj-bdz35/files/VODCA2GPP_v1.nc?download=1'
ds_GPP=xr.open_dataset(pooch.retrieve(url_GPP,known_hash=None))
ds_GPP
-------------------

