Traceback (most recent call last):
  File "/home/wesley/miniconda3/envs/climatematch/lib/python3.10/site-packages/nbclient/client.py", line 778, in _async_poll_for_reply
    msg = await ensure_async(self.kc.shell_channel.get_msg(timeout=new_timeout))
  File "/home/wesley/miniconda3/envs/climatematch/lib/python3.10/site-packages/jupyter_core/utils/__init__.py", line 182, in ensure_async
    result = await obj
  File "/home/wesley/miniconda3/envs/climatematch/lib/python3.10/site-packages/jupyter_client/channels.py", line 315, in get_msg
    raise Empty
_queue.Empty

During handling of the above exception, another exception occurred:

Traceback (most recent call last):
  File "/home/wesley/miniconda3/envs/climatematch/lib/python3.10/site-packages/jupyter_cache/executors/utils.py", line 51, in single_nb_execution
    executenb(
  File "/home/wesley/miniconda3/envs/climatematch/lib/python3.10/site-packages/nbclient/client.py", line 1305, in execute
    return NotebookClient(nb=nb, resources=resources, km=km, **kwargs).execute()
  File "/home/wesley/miniconda3/envs/climatematch/lib/python3.10/site-packages/jupyter_core/utils/__init__.py", line 166, in wrapped
    return loop.run_until_complete(inner)
  File "/home/wesley/miniconda3/envs/climatematch/lib/python3.10/asyncio/base_events.py", line 649, in run_until_complete
    return future.result()
  File "/home/wesley/miniconda3/envs/climatematch/lib/python3.10/site-packages/nbclient/client.py", line 705, in async_execute
    await self.async_execute_cell(
  File "/home/wesley/miniconda3/envs/climatematch/lib/python3.10/site-packages/nbclient/client.py", line 1001, in async_execute_cell
    exec_reply = await self.task_poll_for_reply
  File "/home/wesley/miniconda3/envs/climatematch/lib/python3.10/site-packages/nbclient/client.py", line 802, in _async_poll_for_reply
    error_on_timeout_execute_reply = await self._async_handle_timeout(timeout, cell)
  File "/home/wesley/miniconda3/envs/climatematch/lib/python3.10/site-packages/nbclient/client.py", line 852, in _async_handle_timeout
    raise CellTimeoutError.error_from_timeout_and_cell(
nbclient.exceptions.CellTimeoutError: A cell timed out while it was being executed, after 60 seconds.
The message was: Cell execution timed out.
Here is a preview of the cell contents:
-------------------
['# connect to the AWS S3 bucket for the GPCP Monthly Precipitation CDR data', 'fs = s3fs.S3FileSystem(anon=True)', '', '# get the list of all data files in the AWS S3 bucket', 'file_pattern = "noaa-cdr-precip-gpcp-monthly-pds/data/*/gpcp_v02r03_monthly_*.nc"']
...
['', '# open all the monthly data files and concatenate them along the time dimension', '# this process will take ~ 1 minute to complete due to the number of data files', 'ds = xr.open_mfdataset(file_ob, combine="nested", concat_dim="time")', 'ds']
-------------------

