Traceback (most recent call last):
  File "/home/wesley/miniconda3/envs/climatematch/lib/python3.10/site-packages/nbclient/client.py", line 778, in _async_poll_for_reply
    msg = await ensure_async(self.kc.shell_channel.get_msg(timeout=new_timeout))
  File "/home/wesley/miniconda3/envs/climatematch/lib/python3.10/site-packages/jupyter_core/utils/__init__.py", line 182, in ensure_async
    result = await obj
  File "/home/wesley/miniconda3/envs/climatematch/lib/python3.10/site-packages/jupyter_client/channels.py", line 315, in get_msg
    raise Empty
_queue.Empty

During handling of the above exception, another exception occurred:

Traceback (most recent call last):
  File "/home/wesley/miniconda3/envs/climatematch/lib/python3.10/site-packages/jupyter_cache/executors/utils.py", line 51, in single_nb_execution
    executenb(
  File "/home/wesley/miniconda3/envs/climatematch/lib/python3.10/site-packages/nbclient/client.py", line 1305, in execute
    return NotebookClient(nb=nb, resources=resources, km=km, **kwargs).execute()
  File "/home/wesley/miniconda3/envs/climatematch/lib/python3.10/site-packages/jupyter_core/utils/__init__.py", line 166, in wrapped
    return loop.run_until_complete(inner)
  File "/home/wesley/miniconda3/envs/climatematch/lib/python3.10/asyncio/base_events.py", line 649, in run_until_complete
    return future.result()
  File "/home/wesley/miniconda3/envs/climatematch/lib/python3.10/site-packages/nbclient/client.py", line 705, in async_execute
    await self.async_execute_cell(
  File "/home/wesley/miniconda3/envs/climatematch/lib/python3.10/site-packages/nbclient/client.py", line 1001, in async_execute_cell
    exec_reply = await self.task_poll_for_reply
  File "/home/wesley/miniconda3/envs/climatematch/lib/python3.10/site-packages/nbclient/client.py", line 802, in _async_poll_for_reply
    error_on_timeout_execute_reply = await self._async_handle_timeout(timeout, cell)
  File "/home/wesley/miniconda3/envs/climatematch/lib/python3.10/site-packages/nbclient/client.py", line 852, in _async_handle_timeout
    raise CellTimeoutError.error_from_timeout_and_cell(
nbclient.exceptions.CellTimeoutError: A cell timed out while it was being executed, after 60 seconds.
The message was: Cell execution timed out.
Here is a preview of the cell contents:
-------------------
["# SSP1-2.6 - 'WBGT_day_MPI-ESM1-2-HR_ssp126_r1i1p1f1_raw_runmean7_yearmax.nc'", 'filename_SSP126 = "WBGT_day_MPI-ESM1-2-HR_ssp126_r1i1p1f1_raw_runmean7_yearmax.nc"', 'url_SSP126 = "https://osf.io/67b8m/download"', 'wetbulb_126 = xr.open_dataset(pooch_load(url_SSP126, filename_SSP126)).WBGT', 'wetbulb_126.attrs["units"] = "degC"']
...
['filename_SSP585 = "WBGT_day_MPI-ESM1-2-HR_ssp585_r1i1p1f1_raw_runmean7_yearmax.nc"', 'url_SSP585 = "https://osf.io/pr456/download"', 'wetbulb_585 = xr.open_dataset(pooch_load(url_SSP585, filename_SSP585)).WBGT', 'wetbulb_585.attrs["units"] = "degC"', 'wetbulb_585 = wetbulb_585.resample(time="1Y").mean()']
-------------------

